Workbook

Sheet Vue Globale des Racks
B2: Nbre d'emplacements 'VIDE" | E2: =COUNTBLANK(F7:F174) -> 16
B4: LOCALISATION | F4: PALETTE
B5: ALLÉE | C5: RACK | D5: EMPLACEMENT | E5: HAUTEUR PAL MAX | F5: Actuellement à l'emplacement ?
B7: ALLÉE 1 | C7: A | D7: A001 | E7: ='Allée 1'!N9 -> 1m80 | F7: ='Allée 1'!S9 -> Complexe Meno 12/11/2028
D8: A002 | E8: ='Allée 1'!N9 -> 1m80 | F8: ='Allée 1'!Q9 -> Complexe Meno 12/11/2028
D9: A003 | E9: ='Allée 1'!N9 -> 1m80 | F9: ='Allée 1'!O9 -> Complexe Meno 12/11/2028
D10: A004 | E10: ='Allée 1'!G9 -> 1m28 | F10: ='Allée 1'!J9 -> Complexe Sommeil 26/10/2028
D11: A005 | E11: ='Allée 1'!G9 -> 1m28 | F11: ='Allée 1'!H9 -> Complexe Sommeil 26/10/2028
D12: A101 | E12: ='Allée 1'!N6 -> 1m28 | F12: ='Allée 1'!S6 -> Complexe PDP 01/10/2028
D13: A102 | E13: ='Allée 1'!N6 -> 1m28 | F13: ='Allée 1'!Q6 -> Complexe PDP 01/10/2028
D14: A103 | E14: ='Allée 1'!N6 -> 1m28 | F14: ='Allée 1'!O6 -> Complexe PDP 01/10/2028
D15: A104 | E15: ='Allée 1'!G6 -> 1m28 | F15: ='Allée 1'!J6
D16: A105 | E16: ='Allée 1'!G6 -> 1m28 | F16: ='Allée 1'!H6
D17: A201 | E17: ='Allée 1'!N3 -> 1m28 | F17: ='Allée 1'!S3 -> Complexe PDP 01/10/2028
D18: A202 | E18: ='Allée 1'!N3 -> 1m28 | F18: ='Allée 1'!Q3 -> Complexe PDP 01/10/2028
D19: A203 | E19: ='Allée 1'!N3 -> 1m28 | F19: ='Allée 1'!O3 -> Complexe PDP 01/10/2028
D20: A204 | E20: ='Allée 1'!G3 -> 1m28 | F20: ='Allée 1'!J3 -> ⚠️ Impossible de stocker
D21: A205 | E21: ='Allée 1'!G3 -> 1m28 | F21: ='Allée 1'!H3 -> ⚠️ Impossible de stocker
C22: B | D22: B001 | E22: ='Allée 1'!Y13 -> 1m80 | F22: ='Allée 1'!X13 -> Complexe Coupe-Faim 27/10/2028
D23: B002 | E23: ='Allée 1'!U13 -> 1m80 | F23: ='Allée 1'!V13 -> Complexe PDP 29/10/2028
D24: B003 | E24: ='Allée 1'!U13 -> 1m80 | F24: ='Allée 1'!S13 -> Complexe PDP 29/10/2028
D25: B004 | E25: ='Allée 1'!U13 -> 1m80 | F25: ='Allée 1'!Q13 -> Complexe Méno 12/11/2028
D26: B005 | E26: ='Allée 1'!U13 -> 1m80 | F26: ='Allée 1'!O13 -> COUPE FAIM 12/28
D27: B006 | E27: ='Allée 1'!I13 -> 1m28 | F27: ='Allée 1'!M13 -> Complexe PDP 10/2028
D28: B007 | E28: ='Allée 1'!I13 -> 1m28 | F28: ='Allée 1'!L13 -> Complexe PDP 10/2028
D29: B008 | E29: ='Allée 1'!I13 -> 1m28 | F29: ='Allée 1'!J13 -> Complexe PDP 01/10/2028
D30: B009 | E30: ='Allée 1'!C13 -> 1m28 | F30: ='Allée 1'!G13 -> Complexe PDP 01/10/2028
D31: B010 | E31: ='Allée 1'!C13 -> 1m28 | F31: ='Allée 1'!F13 -> Complexe PDP 24/11/2028
D32: B011 | E32: ='Allée 1'!C13 -> 1m28 | F32: ='Allée 1'!D13 -> Méno 08/12/28
D33: B101 | E33: ='Allée 1'!Y16 -> 1m28 | F33: ='Allée 1'!X17 -> POIDS 11/28
D34: B102 | E34: ='Allée 1'!Y16 -> 1m28 | F34: ='Allée 1'!V17 -> POIDS 11/28
D35: B103 | E35: ='Allée 1'!U16 -> 1m28 | F35: ='Allée 1'!S17 -> poids 11/28
D36: B104 | E36: ='Allée 1'!U16 -> 1m28 | F36: ='Allée 1'!Q17 -> POIDS 11/28
D37: B105 | E37: ='Allée 1'!U16 -> 1m28 | F37: ='Allée 1'!O17 -> Copupr faim 12/28
D38: B106 | E38: ='Allée 1'!I15 -> 1m28 | F38: ='Allée 1'!M16 -> Complexe PDP 10/2028
D39: B107 | E39: ='Allée 1'!I15 -> 1m28 | F39: ='Allée 1'!L16 -> Complexe PDP 10/2028
D40: B108 | E40: ='Allée 1'!I15 -> 1m28 | F40: ='Allée 1'!J16 -> Complexe PDP 10/2028
D41: B109 | E41: ='Allée 1'!C15 -> 1m28 | F41: ='Allée 1'!G16 -> Complexe PDP 01/10/2028
D42: B110 | E42: ='Allée 1'!C15 -> 1m28 | F42: ='Allée 1'!F16 -> Complexe PDP 10/2028
D43: B111 | E43: ='Allée 1'!C15 -> 1m28 | F43: ='Allée 1'!D16 -> Complexe PDP 29/10/2028
...

Sheet Allée 1
B2: ESPACE | L2: ESPACE | V2: ESPACE
G3: 1m28 | H3: ⚠️ Impossible de stocker | J3: ⚠️ Impossible de stocker | N3: 1m28 | O3: Complexe PDP 01/10/2028 | Q3: Complexe PDP 01/10/2028 | S3: Complexe PDP 01/10/2028 | X3: Porte | Z3: d'entrée
H4: A205 | J4: A204 | O4: A203 | Q4: A202 | S4: A201
G6: 1m28 | N6: 1m28 | O6: Complexe PDP 01/10/2028 | Q6: Complexe PDP 01/10/2028 | S6: Complexe PDP 01/10/2028
H7: A105 | J7: A104 | O7: A103 | Q7: A102 | S7: A101
G9: 1m28 | H9: Complexe Sommeil 26/10/2028 | J9: Complexe Sommeil 26/10/2028 | N9: 1m80 | O9: Complexe Meno 12/11/2028 | Q9: Complexe Meno 12/11/2028 | S9: Complexe Meno 12/11/2028
H10: A005 | J10: A004 | O10: A003 | Q10: A002 | S10: A001
B11: Volet Roulant | D11: < < < Allée 1 < < <
D12: B011 | F12: B010 | G12: B009 | J12: B008 | L12: B007 | M12: B006 | O12: B005 | Q12: B004 | S12: B003 | V12: B002 | X12: B001
C13: 1m28 | D13: Méno 08/12/28 | F13: Complexe PDP 24/11/2028 | G13: Complexe PDP 01/10/2028 | I13: 1m28 | J13: Complexe PDP 01/10/2028 | L13: Complexe PDP 10/2028 | M13: Complexe PDP 10/2028 | O13: COUPE FAIM 12/28 | Q13: Complexe Méno 12/11/2028 | S13: Complexe PDP 29/10/2028 | U13: 1m80 | V13: Complexe PDP 29/10/2028 | X13: Complexe Coupe-Faim 27/10/2028 | Y13: 1m80
C15: 1m28 | D15: B111 | F15: B110 | G15: B109 | I15: 1m28 | J15: B108 | L15: B107 | M15: B106
D16: Complexe PDP 29/10/2028 | F16: Complexe PDP 10/2028 | G16: Complexe PDP 01/10/2028 | J16: Complexe PDP 10/2028 | L16: Complexe PDP 10/2028 | M16: Complexe PDP 10/2028 | O16: B105 | Q16: B104 | S16: B103 | U16: 1m28 | V16: B102 | X16: B101 | Y16: 1m28
O17: Copupr faim 12/28 | Q17: POIDS 11/28 | S17: poids 11/28 | V17: POIDS 11/28 | X17: POIDS 11/28
C19: 65cm | D19: B211 | F19: B210 | G19: B209 | I19: 1m28 | J19: B208 | L19: B207 | M19: B206
D20: ⚠️ Impossible de stocker | F20: Complexe PDP 01/10/2028 | G20: Coupe-faim 12/28 | J20: Poids 24/11/28 | L20: COUPE FAIM 12/28 | M20: Poids 11/28 | O20: B205 | Q20: B204 | S20: B203 | U20: 1m28 | V20: B202 | X20: B201 | Y20: 1m28
O21: Sommeil 11/28 | Q21: POPIDS 11/28 | S21: Méno 12/28 | V21: POIDS 11/28 | X21: POIDS 11/28

Sheet Allée 2
P2: ⚠️ Impossible de stocker" | R2: Complexe PDP 14/07/2028 | S2: Complexe PDP 14/07/2028 | T2: 1m15 | U2: SOMMEIL 11/28 | W2: Méno 12/28 | Y2: 1m15
C3: 65cm | D3: ⚠️ Impossible de stocker | F3: ⚠️ Impossible de stocker | H3: Complexe Méno 02/09/2028 | J3: 1m28 | K3: Complexe Méno 02/09/2028 | M3: Complexe Méno 02/09/2028 | N3: Complexe Méno 02/09/2028 | O3: 65cm
P4: C205 | R4: C204 | S4: C203 | U4: C202 | W4: C201
D5: C211 | F5: C210 | H5: C209 | K5: C208 | M5: C207 | N5: C206
P6: Complexe PDP 14/07/2028 | R6: Complexe PDP 14/07/2028 | S6: Complexe PDP 14/07/2028 | T6: 1m28 | U6: POIDS 11/28 | W6: POIDS 11/28 | Y6: 1m28
C7: 1m28 | D7: Complexe PDP 14/07/2028 | F7: Complexe PDP 14/07/2028 | H7: Complexe PDP 14/07/2028 | J7: 1m15 | K7: Complexe Méno 02/09/2028 | M7: Complexe Méno 02/09/2028 | N7: Complexe Méno 02/09/2028 | O7: 1m28
P8: C105 | R8: C104 | S8: C103 | U8: C102 | W8: C101
D9: C111 | F9: C110 | H9: C109 | K9: C108 | M9: C107 | N9: C106
P10: Enveloppes ENV20 2 flacons | R10: Carton 6 flacons | S10: C/3 EXTRA | T10: 1m80 | U10: Complexe PDP 29/10/2028 | W10: Complexe PDP 29/10/2028 | Y10: 1m80
C11: 1m28 | D11: Complexe Sommeil 05/10/2028 | F11: coupe faim 12/28 | H11: Complexe Coupe-Faim 08/2028 | J11: 1m28 | K11: poids 11/28 | M11: Carton 12 Flacons | O11: 1m28
D12: C011 | F12: C010 | H12: C009 | K12: C008 | M12: C007 | N12: C006 | P12: C005 | R12: C004 | S12: C003 | U12: C002 | W12: C001
B13: < < < Allée 2 < < < | Z13: Toilettes
C14: 1m28 | D14: D009 | F14: D008 | H14: D007 | J14: 1m30 | K14: D006 | M14: D005 | N14: D004 | P14: D003 | R14: D002 | S14: D001 | T14: 1m80
D15: Complexe Coupe-Faim 08/2028 | F15: Complexe Sommeil 05/10/2028 | H15: Complexe PDP 01/10/2028 | K15: Complexe Méno 23/06/2028 | M15: Complexe Méno 02/09/2028 | N15: Complexe Méno 02/09/2028 | P15: Complexe Poids 14/07/2028 | R15: Complexe PDP 24/11/2028 | S15: Complexe anxiete, peurs 10/2028
C17: 1m28 | D17: D109 | F17: D108 | H17: D107 | J17: 1m28 | K17: D106 | M17: D105 | N17: D104
D18: poids 11/28 | F18: Complexe Coupe-Faim 31/08/2028 | H18: Complexe Coupe-Faim 08/2028 | K18: Complexe Méno 02/09/2028 | M18: Complexe Méno 02/09/2028 | N18: poids 11/28 | O18: 1m28 | P18: D103 | R18: D102 | S18: D101 | T18: 1m28
P19: méno 12/28 | R19: Complexe PDP 14/07/2028 | S19: Complexe PDP 01/10/2028
C21: 65cm | D21: D209 | F21: D208 | H21: D207 | J21: 1m28 | K21: D206 | M21: D205 | N21: D204
D22: ⚠️ Impossible de stocker | F22: Complexe Coupe-Faim 31/08/2028 | H22: Complexe Coupe-Faim 08/2028 | K22: Complexe Méno 02/09/2028 | M22: Complexe PDP 01/10/2028 | N22: Complexe Méno 02/09/2028 | O22: 65cm | P22: D203 | R22: D202 | S22: D201 | T22: 1m28
R23: Complexe PDP 01/10/2028 | S23: Complexe PDP 01/10/2028

Sheet Allée 3
C3: 65cm | D3: ⚠️ Impossible de stocker | F3: TDO Je rayonne jour après jour | H3: TDO Quartz Moyen troué Moyen non-toué | J3: 1m28 | K3: TDO Oracle de la lune | M3: coupe-faim 12/28 | N3: sommeil 11/28 | O3: 65cm | P3: B/2 eco PETITE PALETTE CAR NEON | T3: 1m28 | U3: POSTE DE TRAVAIL
D5: E201 | F5: E202 | H5: E203 | K5: E204 | M5: E205 | N5: E206 | P5: E207 | R5: E208 | S5: E209
C7: 1m28 | D7: poids 11/28 | F7: POIDS11/28 | J7: 1m28 | K7: E/5 EXTRA | M7: poids 11/28 | N7: anxiet 11/28 | O7: 1m28 | P7: B/2 eco | R7: D/4 eco | S7: D/4 eco | T7: 1m28
D9: E101 | F9: E102 | H9: E103 | K9: E104 | M9: E105 | N9: E106 | P9: E107 | R9: E108 | S9: E109
C11: 1m28 | D11: Enveloppes Facteur Livre ENV50 | F11: Stock sécu poids 3 flacons | H11: Stock sécu poids 2 flacons | J11: 1m28 | K11: Stock sécu poids 1 flacon | M11: Stock sécu Méno 2 flacons | N11: Stock sécu poids 2 flacons | O11: 1m28 | P11: Stock sécu pack minceur | R11: Stock Sécu Bloc Box | S11: Stock Sécu Bloc Box | T11: 1m80
D12: E001 | F12: E002 | H12: E003 | K12: E004 | M12: E005 | N12: E006 | P12: E007 | R12: E008 | S12: E009
C13: > > > Allée 3 > > >
C14: 1m28 | D14: F001 | F14: F002 | H14: F003 | J14: 1m28 | K14: F004 | M14: F005 | N14: F006 | O14: 1m28 | P14: F007 | R14: F008 | S14: F009 | T14: 1m80
D15: K & S PARFUMS Stock | F15: Stock sécu C/3 EXTRA | H15: Divers Famillia WEB2CO | K15: TDO defunts fees abondance univers energie et créa | M15: TDO Carnet Emotions Carnet Gratitude Carnet des Emotions | N15: TDO Oracle Mantras Oracle Message de l'amour | P15: Stock Sécu 4 Flacons | S15: Stock Sécu 6 Flacons
C17: 1m28 | D17: F101 | F17: F102 | H17: F103 | J17: 1m28 | K17: F104 | M17: F105 | N17: F106 | O17: 1m28 | P17: F107 | R17: F108 | S17: F109 | T17: 1m28
K18: TDO Oracle des flammes jumelles | M18: TDO Carnet de Lune | N18: TDO Oracle pratique du Yoga | P18: C/3 ECO | R18: J/9 EXTRA
C21: 65cm | D21: F201 | F21: F202 | H21: F203 | J21: 1m28 | K21: F204 | M21: F205 | N21: F206 | O21: 1m28 | P21: F207 | R21: F208 | S21: F209 | T21: 1m28
D22: ⚠️ Impossible de stocker | F22: ⚠️ Impossible de stocker | H22: TDO | K22: Message de l'âme | M22: TDO carnet envies carnet intuitions | N22: TDO Oracle Essence du Yoga

Sheet Zone de Picking
C2: 1m28 | D2: Consommables ANGELS UNIVERSE | E2: ⚠️ Impossible de stocker | F2: 0cm
D3: G201 | E3: G202
C5: 1m28 | D5: Consommables ANGELS UNIVERSE | E5: ⚠️ Impossible de stocker | F5: 0cm
D6: G101 | E6: G102
C8: 1m80 | D8: Coffret Angels Universe | E8: Consommables Angels universe | F8: 1m80
D9: G001 | E9: G002
